INFO:     Started server process [2001229]
INFO:     Waiting for application startup.
INFO:     Application startup complete.
INFO:     Uvicorn running on http://10.0.0.10:8888 (Press CTRL+C to quit)
Servicio de estimacion inicializado en el puerto 6767
Iniciando el API de Estimaci√≥n
Esperando solicitudes...
INFO:     10.8.0.66:62471 - "GET /estimacion HTTP/1.1" 200 OK
INFO:     10.8.0.66:61794 - "GET /estimacion HTTP/1.1" 200 OK
INFO:     10.8.0.66:52743 - "GET /estimacion HTTP/1.1" 200 OK
INFO:     10.8.0.66:61951 - "GET /estimacion HTTP/1.1" 200 OK
Exception in thread Thread-1:
Traceback (most recent call last):
  File "/usr/lib/python3/dist-packages/urllib3/connection.py", line 159, in _new_conn
    conn = connection.create_connection(
  File "/usr/lib/python3/dist-packages/urllib3/util/connection.py", line 84, in create_connection
    raise err
  File "/usr/lib/python3/dist-packages/urllib3/util/connection.py", line 74, in create_connection
    sock.connect(sa)
ConnectionRefusedError: [Errno 111] Connection refused

During handling of the above exception, another exception occurred:

Traceback (most recent call last):
  File "/usr/lib/python3/dist-packages/urllib3/connectionpool.py", line 665, in urlopen
    httplib_response = self._make_request(
  File "/usr/lib/python3/dist-packages/urllib3/connectionpool.py", line 387, in _make_request
    conn.request(method, url, **httplib_request_kw)
  File "/usr/lib/python3.8/http/client.py", line 1256, in request
    self._send_request(method, url, body, headers, encode_chunked)
  File "/usr/lib/python3.8/http/client.py", line 1302, in _send_request
    self.endheaders(body, encode_chunked=encode_chunked)
  File "/usr/lib/python3.8/http/client.py", line 1251, in endheaders
    self._send_output(message_body, encode_chunked=encode_chunked)
  File "/usr/lib/python3.8/http/client.py", line 1011, in _send_output
    self.send(msg)
  File "/usr/lib/python3.8/http/client.py", line 951, in send
    self.connect()
  File "/usr/lib/python3/dist-packages/urllib3/connection.py", line 187, in connect
    conn = self._new_conn()
  File "/usr/lib/python3/dist-packages/urllib3/connection.py", line 171, in _new_conn
    raise NewConnectionError(
urllib3.exceptions.NewConnectionError: <urllib3.connection.HTTPConnection object at 0x7f27c4546160>: Failed to establish a new connection: [Errno 111] Connection refused

During handling of the above exception, another exception occurred:

Traceback (most recent call last):
  File "/usr/lib/python3/dist-packages/requests/adapters.py", line 439, in send
    resp = conn.urlopen(
  File "/usr/lib/python3/dist-packages/urllib3/connectionpool.py", line 719, in urlopen
    retries = retries.increment(
  File "/usr/lib/python3/dist-packages/urllib3/util/retry.py", line 436, in increment
    raise MaxRetryError(_pool, url, error or ResponseError(cause))
urllib3.exceptions.MaxRetryError: HTTPConnectionPool(host='localhost', port=13000): Max retries exceeded with url: /migrar (Caused by NewConnectionError('<urllib3.connection.HTTPConnection object at 0x7f27c4546160>: Failed to establish a new connection: [Errno 111] Connection refused'))

During handling of the above exception, another exception occurred:

Traceback (most recent call last):
  File "/usr/lib/python3.8/threading.py", line 932, in _bootstrap_inner
    self.run()
  File "/usr/lib/python3.8/threading.py", line 870, in run
    self._target(*self._args, **self._kwargs)
  File "Estimador.py", line 59, in socket_listener
    alertarMigrador()
  File "Estimador.py", line 125, in alertarMigrador
    response = requests.post(endpoint, json=body)
  File "/usr/lib/python3/dist-packages/requests/api.py", line 119, in post
    return request('post', url, data=data, json=json, **kwargs)
  File "/usr/lib/python3/dist-packages/requests/api.py", line 61, in request
    return session.request(method=method, url=url, **kwargs)
  File "/usr/lib/python3/dist-packages/requests/sessions.py", line 530, in request
    resp = self.send(prep, **send_kwargs)
  File "/usr/lib/python3/dist-packages/requests/sessions.py", line 643, in send
    r = adapter.send(request, **kwargs)
  File "/usr/lib/python3/dist-packages/requests/adapters.py", line 516, in send
    raise ConnectionError(e, request=request)
requests.exceptions.ConnectionError: HTTPConnectionPool(host='localhost', port=13000): Max retries exceeded with url: /migrar (Caused by NewConnectionError('<urllib3.connection.HTTPConnection object at 0x7f27c4546160>: Failed to establish a new connection: [Errno 111] Connection refused'))
INFO:     10.8.0.66:54919 - "GET /estimacion HTTP/1.1" 200 OK
INFO:     10.8.0.66:51099 - "GET /estimacion HTTP/1.1" 200 OK
INFO:     10.8.0.66:51118 - "GET /estimacion HTTP/1.1" 200 OK
INFO:     10.8.0.66:51118 - "GET /estimacion HTTP/1.1" 200 OK
INFO:     10.8.0.66:51118 - "GET /estimacion HTTP/1.1" 200 OK
INFO:     10.8.0.66:51118 - "GET /estimacion HTTP/1.1" 200 OK
INFO:     10.8.0.66:62700 - "GET /estimacion HTTP/1.1" 200 OK
